<?xml version="1.0"?>
<robot xmlns:xacro="http://www.ros.org/wiki/xacro" name="simple_rover">
  <xacro:property name="wheel_separation" value="0.375" />
  <xacro:property name="wheel_radius" value="0.3" />
  <xacro:property name="caster_wheel_radius" value="0.2" />
  <xacro:property name="wheel_width" value="0.25" />
  <xacro:property name="body_height" value="1.0" />
  <xacro:property name="body_width" value="0.5" />
  <xacro:property name="body_length" value="0.3" />
  <xacro:include filename="camera.urdf.xacro"/>
  
  <gazebo reference="chassis">
    <material>Gazebo/White</material>
    <mu1>0.2</mu1>
    <mu2>0.2</mu2>
  </gazebo>

  <gazebo reference="right_wheel">
    <material>Gazebo/Red</material>
    <mu1>0.84</mu1>
    <mu2>0.84</mu2>
  </gazebo>

  <gazebo reference="left_wheel">
    <material>Gazebo/Red</material>
    <mu1>0.84</mu1>
    <mu2>0.84</mu2>
  </gazebo>

  <gazebo reference="caster_wheel">
    <material>Gazebo/Black</material>
    <mu1>0.84</mu1>
    <mu2>0.84</mu2>
  </gazebo>

  <gazebo reference="camera_link">
    <material>Gazebo/Blue</material>
    <mu1>0.84</mu1>
    <mu2>0.84</mu2>
  </gazebo>
  
  <link name="chassis">
    <visual>
      <geometry>
        <box size="${body_height} ${body_width} ${body_length}"/>
      </geometry>
    </visual>
    <collision>
      <geometry>
        <box size="${body_height} ${body_width} ${body_length}"/>
      </geometry>
    </collision>

    <inertial>
      <mass value="1"/>
      <inertia ixx="0.166667" ixy="0" ixz="0" iyy="0.166667" iyz="0" izz="0.166667"/>
    </inertial>
  </link>

  <link name="left_wheel">
    <visual>
      <geometry>
        <!-- IMPLEMENT HERE -->
        <cylinder radius="${wheel_radius}" length="${wheel_width}"/>
      </geometry>
    </visual>

    <collision>
      <geometry>
        <!-- IMPLEMENT HERE -->
        <cylinder radius="${wheel_radius}" length="${wheel_width}"/>
      </geometry>
    </collision>

    <inertial>
      <mass value="1"/>
      <inertia ixx="0.145833" ixy="0.0" ixz="0.0" iyy="0.145833" iyz="0.0" izz="0.125"/>
    </inertial>
  </link>

  <link name="right_wheel">
    <visual>
      <geometry>
        <!-- IMPLEMENT HERE -->
        <cylinder radius="${wheel_radius}" length="${wheel_width}"/>
      </geometry>
    </visual>

    <collision>
      <geometry>
        <!-- IMPLEMENT HERE -->
        <cylinder radius="${wheel_radius}" length="${wheel_width}"/>
      </geometry>
    </collision>

    <inertial>
      <mass value="1"/>
      <inertia ixx="0.145833" ixy="0.0" ixz="0.0" iyy="0.145833" iyz="0.0" izz="0.125"/>
    </inertial>  
  </link>

  <link name="caster_wheel">
    <visual>
      <geometry>
        <!-- IMPLEMENT HERE -->
        <sphere radius="${caster_wheel_radius}"/>
      </geometry>
    </visual>

    <collision>
      <geometry>
        <!-- IMPLEMENT HERE -->
        <sphere radius="${caster_wheel_radius}"/>
      </geometry>
    </collision>

    <inertial>
      <mass value="1"/>
      <inertia ixx="0.1" ixy="0.0" ixz="0.0" iyy="0.1" iyz="0.0" izz="0.1"/>
    </inertial>  
  </link>

  <link name="camera_link">
    <visual>
      <geometry>
        <box size="0.01 0.01 0.01"/>
      </geometry>
    </visual>
  </link>

  <joint name="joint_left" type="continuous">
    <!-- IMPLEMENT HERE -->
    <parent link="chassis"/>
    <child link="left_wheel"/>
    <origin rpy="${pi / 2} 0 0" xyz="0.25 -${wheel_separation} 0"/>
    <axis xyz="0 0 1"/>
    <dynamics friction="0.1"/>
  </joint>


  <joint name="joint_right" type="continuous">
    <!-- IMPLEMENT HERE -->
    <parent link="chassis"/>
    <child link="right_wheel"/>
    <origin rpy="${pi / 2} 0 0" xyz="0.25 ${wheel_separation} 0"/>
    <axis xyz="0 0 1"/>
    <dynamics friction="0.1"/>
  </joint>

  <joint name="joint_caster_wheel" type="continuous">
    <!-- IMPLEMENT HERE --> 
    <parent link="chassis"/>
    <child link="caster_wheel"/>
    <origin rpy="${pi / 2} 0 0" xyz="-0.25 0 -0.1"/>
    <axis xyz="0 0 1"/>
    <dynamics friction="0.1"/>
  </joint>

  <joint name="camera_joint" type="fixed">
    <parent link="chassis"/>
    <child link="camera_link"/>
    <origin xyz="-0.495 0 0.155" rpy="${pi} ${pi} 0"/>
  </joint>

  <xacro:macro name="diff_drive_plugin" params="left_joint right_joint wheel_separation">
    <gazebo>
      <plugin name="simple_rover_diff_drive" filename="libgazebo_ros_diff_drive.so">
        <update_rate>30</update_rate>

        <!-- wheels -->
        <left_joint>joint_left</left_joint>
        <right_joint>joint_right</right_joint>

        <!-- kinematics -->
        <wheel_separation>${wheel_separation}</wheel_separation>
        <wheel_diameter>0.28</wheel_diameter>

        <!-- limits -->
        <max_wheel_torque>20</max_wheel_torque>
        <max_wheel_acceleration>1.0</max_wheel_acceleration>

        <!-- Receive velocity commands on this ROS topic -->
        <command_topic>cmd_vel</command_topic>
      </plugin>
    </gazebo>
  </xacro:macro>

  <xacro:diff_drive_plugin left_joint="joint_left" right_joint="joint_right" wheel_separation="${wheel_separation}"/>
  <xacro:normal_camera robot_name="simple_rover"/>
</robot>
